Workbook

Sheet Guide
A1: English words and clues for Granny's Puzzle
A3: What's here
A4: Every English word the game can use, one sheet per length, easiest first. The words, difficulties and definitions came from SCOWL and WordNet (free word lists); the clues already written are filled in. This file is now the record: the importer builds the game's word list from it.
A6: What to do
A7: Write clues in Clue 1 to 3. Start with Easy, then Medium: those are the words levels use. A word with no clue is fine; it waits until it gets one.
A8: To add a word, write it in an empty row at the bottom of its length's sheet, lowercase, with a difficulty. To remove a word, delete its whole row.
A9: Use the filter arrows in the header row to show, for example, only Easy words with an empty Clue 1.
A11: Columns
A12: Difficulty: Easy = everyone knows it. Medium = normal adult vocabulary. Hard = less common. Rare = unusual, crossword-veteran words; change any you disagree with.
A13: Definition (grey): what the word means, from WordNet, as a help. Not shown in the game. Check it: WordNet sometimes lists a less common meaning first.
A14: The beige columns (ID, Letters, Len) fill themselves.
A16: Clue rules (CLUE_STYLE.md has them all)
... A25: Word: card · Difficulty: Easy · Clue 1: Credit ___ · Clue 2: Birthday greeting · Clue 3: Deck member

Sheet Summary
A1: Sheet | B1: Words | C1: With a clue | D1: Easy | E1: Medium | F1: Hard | G1: Rare | H1: Easy + Medium still to clue
A2: 2 letters | B2: =COUNTA('2 letters'!B2:B529) -> 28 | C2: =COUNTIFS('2 letters'!B2:B529,"<>",'2 letters'!F2:F529,"<>") -> 22 | D2: =COUNTIF('2 letters'!D2:D529,"Easy") -> 21 | E2: =COUNTIF('2 letters'!D2:D529,"Medium") -> 2 | F2: =COUNTIF('2 letters'!D2:D529,"Hard") -> 4 | G2: =COUNTIF('2 letters'!D2:D529,"Rare") -> 1 | H2: =COUNTIFS('2 letters'!D2:D529,"Easy",'2 letters'!F2:F529,"")+COUNTIFS('2 letters'!D2:D529,"Medium",'2 letters'!F2:F529,"") -> 1
A3: 3 letters | B3: =COUNTA('3 letters'!B2:B929) -> 428 | C3: =COUNTIFS('3 letters'!B2:B929,"<>",'3 letters'!F2:F929,"<>") -> 147 | D3: =COUNTIF('3 letters'!D2:D929,"Easy") -> 127 | E3: =COUNTIF('3 letters'!D2:D929,"Medium") -> 97 | F3: =COUNTIF('3 letters'!D2:D929,"Hard") -> 171 | G3: =COUNTIF('3 letters'!D2:D929,"Rare") -> 33 | H3: =COUNTIFS('3 letters'!D2:D929,"Easy",'3 letters'!F2:F929,"")+COUNTIFS('3 letters'!D2:D929,"Medium",'3 letters'!F2:F929,"") -> 77
A4: 4 letters | B4: =COUNTA('4 letters'!B2:B1959) -> 1458 | C4: =COUNTIFS('4 letters'!B2:B1959,"<>",'4 letters'!F2:F1959,"<>") -> 211 | D4: =COUNTIF('4 letters'!D2:D1959,"Easy") -> 363 | E4: =COUNTIF('4 letters'!D2:D1959,"Medium") -> 342 | F4: =COUNTIF('4 letters'!D2:D1959,"Hard") -> 603 | G4: =COUNTIF('4 letters'!D2:D1959,"Rare") -> 150 | H4: =COUNTIFS('4 letters'!D2:D1959,"Easy",'4 letters'!F2:F1959,"")+COUNTIFS('4 letters'!D2:D1959,"Medium",'4 letters'!F2:F1959,"") -> 494
A5: 5 letters | B5: =COUNTA('5 letters'!B2:B2559) -> 2058 | C5: =COUNTIFS('5 letters'!B2:B2559,"<>",'5 letters'!F2:F2559,"<>") -> 178 | D5: =COUNTIF('5 letters'!D2:D2559,"Easy") -> 367 | E5: =COUNTIF('5 letters'!D2:D2559,"Medium") -> 410 | F5: =COUNTIF('5 letters'!D2:D2559,"Hard") -> 989 | G5: =COUNTIF('5 letters'!D2:D2559,"Rare") -> 292 | H5: =COUNTIFS('5 letters'!D2:D2559,"Easy",'5 letters'!F2:F2559,"")+COUNTIFS('5 letters'!D2:D2559,"Medium",'5 letters'!F2:F2559,"") -> 599
A6: 6 letters | B6: =COUNTA('6 letters'!B2:B3183) -> 2682 | C6: =COUNTIFS('6 letters'!B2:B3183,"<>",'6 letters'!F2:F3183,"<>") -> 159 | D6: =COUNTIF('6 letters'!D2:D3183,"Easy") -> 352 | E6: =COUNTIF('6 letters'!D2:D3183,"Medium") -> 458 | F6: =COUNTIF('6 letters'!D2:D3183,"Hard") -> 1433 | G6: =COUNTIF('6 letters'!D2:D3183,"Rare") -> 439 | H6: =COUNTIFS('6 letters'!D2:D3183,"Easy",'6 letters'!F2:F3183,"")+COUNTIFS('6 letters'!D2:D3183,"Medium",'6 letters'!F2:F3183,"") -> 651
A7: 7 letters | B7: =COUNTA('7 letters'!B2:B3502) -> 3001 | C7: =COUNTIFS('7 letters'!B2:B3502,"<>",'7 letters'!F2:F3502,"<>") -> 0 | D7: =COUNTIF('7 letters'!D2:D3502,"Easy") -> 359 | E7: =COUNTIF('7 letters'!D2:D3502,"Medium") -> 540 | F7: =COUNTIF('7 letters'!D2:D3502,"Hard") -> 1520 | G7: =COUNTIF('7 letters'!D2:D3502,"Rare") -> 582 | H7: =COUNTIFS('7 letters'!D2:D3502,"Easy",'7 letters'!F2:F3502,"")+COUNTIFS('7 letters'!D2:D3502,"Medium",'7 letters'!F2:F3502,"") -> 899
A8: 8 letters | B8: =COUNTA('8 letters'!B2:B3346) -> 2845 | C8: =COUNTIFS('8 letters'!B2:B3346,"<>",'8 letters'!F2:F3346,"<>") -> 0 | D8: =COUNTIF('8 letters'!D2:D3346,"Easy") -> 274 | E8: =COUNTIF('8 letters'!D2:D3346,"Medium") -> 483 | F8: =COUNTIF('8 letters'!D2:D3346,"Hard") -> 1419 | G8: =COUNTIF('8 letters'!D2:D3346,"Rare") -> 669 | H8: =COUNTIFS('8 letters'!D2:D3346,"Easy",'8 letters'!F2:F3346,"")+COUNTIFS('8 letters'!D2:D3346,"Medium",'8 letters'!F2:F3346,"") -> 757
A9: Total | B9: =SUM(B2:B8) -> 12500 | C9: =SUM(C2:C8) -> 717 | D9: =SUM(D2:D8) -> 1863 | E9: =SUM(E2:E8) -> 2332 | F9: =SUM(F2:F8) -> 6139 | G9: =SUM(G2:G8) -> 2166 | H9: =SUM(H2:H8) -> 3478
A11: Levels use Easy and Medium words by default (the generator's familiarity cut-off is 20), so the last column is the clue work that matters first. Hard and Rare words only appear if a pack is generated with a higher cut-off.

Sheet 2 letters
A1: ID | B1: Word | C1: Letters | D1: Difficulty | E1: Definition | F1: Clue 1 | G1: Len | H1: Clue 2 | I1: Len | J1: Clue 3 | K1: Len | L1: Notes
A2: =IF(B2="","",ROW()-1) -> 1 | B2: am | C2: =IF(B2="","",LEN(TRIM(B2))) -> 2 | D2: Easy | E2: a radioactive transuranic metallic element | F2: I ___ ready | G2: =IF(F2="","",LEN(F2)) -> 11 | H2: I ___ here | I2: =IF(H2="","",LEN(H2)) -> 10 | K2: =IF(J2="","",LEN(J2))
A3: =IF(B3="","",ROW()-1) -> 2 | B3: an | C3: =IF(B3="","",LEN(TRIM(B3))) -> 2 | D3: Easy | E3: an associate degree in nursing | F3: ___ apple a day | G3: =IF(F3="","",LEN(F3)) -> 15 | H3: ___ hour ago | I3: =IF(H3="","",LEN(H3)) -> 12 | K3: =IF(J3="","",LEN(J3))
A4: =IF(B4="","",ROW()-1) -> 3 | B4: as | C4: =IF(B4="","",LEN(TRIM(B4))) -> 2 | D4: Easy | E4: to the same degree (often followed by `as') | F4: Just ___ good | G4: =IF(F4="","",LEN(F4)) -> 13 | H4: Same ___ before | I4: =IF(H4="","",LEN(H4)) -> 15 | K4: =IF(J4="","",LEN(J4))
A5: =IF(B5="","",ROW()-1) -> 4 | B5: at | C5: =IF(B5="","",LEN(TRIM(B5))) -> 2 | D5: Easy | E5: a highly unstable radioactive element (the heaviest of the halogen series) | F5: Meet ___ noon | G5: =IF(F5="","",LEN(F5)) -> 13 | H5: Located in | I5: =IF(H5="","",LEN(H5)) -> 10 | K5: =IF(J5="","",LEN(J5))
A6: =IF(B6="","",ROW()-1) -> 5 | B6: be | C6: =IF(B6="","",LEN(TRIM(B6))) -> 2 | D6: Easy | E6: have the quality of being | F6: To ___ or not to ___ | G6: =IF(F6="","",LEN(F6)) -> 20 | H6: Exist | I6: =IF(H6="","",LEN(H6)) -> 5 | K6: =IF(J6="","",LEN(J6))
A7: =IF(B7="","",ROW()-1) -> 6 | B7: by | C7: =IF(B7="","",LEN(TRIM(B7))) -> 2 | D7: Easy | E7: so as to pass a given point | F7: Next to | G7: =IF(F7="","",LEN(F7)) -> 7 | H7: Close ___ | I7: =IF(H7="","",LEN(H7)) -> 9 | K7: =IF(J7="","",LEN(J7))
A8: =IF(B8="","",ROW()-1) -> 7 | B8: do | C8: =IF(B8="","",LEN(TRIM(B8))) -> 2 | D8: Easy | E8: engage in | F8: Perform | G8: =IF(F8="","",LEN(F8)) -> 7 | H8: To-___ list | I8: =IF(H8="","",LEN(H8)) -> 11 | K8: =IF(J8="","",LEN(J8))
A9: =IF(B9="","",ROW()-1) -> 8 | B9: go | C9: =IF(B9="","",LEN(TRIM(B9))) -> 2 | D9: Easy | E9: change location | F9: Leave | G9: =IF(F9="","",LEN(F9)) -> 5 | H9: Green light word | I9: =IF(H9="","",LEN(H9)) -> 16 | K9: =IF(J9="","",LEN(J9))
A10: =IF(B10="","",ROW()-1) -> 9 | B10: he | C10: =IF(B10="","",LEN(TRIM(B10))) -> 2 | D10: Easy | E10: a very light colorless element that is one of the six inert gasses | F10: That man | G10: =IF(F10="","",LEN(F10)) -> 8 | H10: Him, as subject | I10: =IF(H10="","",LEN(H10)) -> 15 | K10: =IF(J10="","",LEN(J10))
A11: =IF(B11="","",ROW()-1) -> 10 | B11: in | C11: =IF(B11="","",LEN(TRIM(B11))) -> 2 | D11: Easy | E11: a unit of length equal to one twelfth of a foot | F11: Not out | G11: =IF(F11="","",LEN(F11)) -> 7 | H11: Trendy | I11: =IF(H11="","",LEN(H11)) -> 6 | K11: =IF(J11="","",LEN(J11))
A12: =IF(B12="","",ROW()-1) -> 11 | B12: it | C12: =IF(B12="","",LEN(TRIM(B12))) -> 2 | D12: Easy | E12: the branch of engineering that deals with the use of computers and telecommunications to retrieve and store and transmit information | F12: Tag player | G12: =IF(F12="","",LEN(F12)) -> 10 | H12: That thing | I12: =IF(H12="","",LEN(H12)) -> 10 | K12: =IF(J12="","",LEN(J12))
A13: =IF(B13="","",ROW()-1) -> 12 | B13: me | C13: =IF(B13="","",LEN(TRIM(B13))) -> 2 | D13: Easy | E13: a state in New England | F13: Myself | G13: =IF(F13="","",LEN(F13)) -> 6 | H13: Not you | I13: =IF(H13="","",LEN(H13)) -> 7 | K13: =IF(J13="","",LEN(J13))
... A22: =IF(B22="","",ROW()-1) -> 21 | B22: us | C22: =IF(B22="","",LEN(TRIM(B22))) -> 2 | D22: Easy | E22: North American republic containing 50 states - 48 conterminous states in North America plus Alaska in northwest North America and the Hawaiian Islands in the Pacific Ocean | F22: You and me | G22: =IF(F22="","",LEN(F22)) -> 10 | H22: We, as object | I22: =IF(H22="","",LEN(H22)) -> 13 | K22: =IF(J22="","",LEN(J22))
A23: =IF(B23="","",ROW()-1) -> 22 | B23: ax | C23: =IF(B23="","",LEN(TRIM(B23))) -> 2 | D23: Medium | E23: an edge tool with a heavy bladed head mounted across a handle | G23: =IF(F23="","",LEN(F23)) | I23: =IF(H23="","",LEN(H23)) | K23: =IF(J23="","",LEN(J23))
A24: =IF(B24="","",ROW()-1) -> 23 | B24: ha | C24: =IF(B24="","",LEN(TRIM(B24))) -> 2 | D24: Medium | E24: (astronomy) the angular distance of a celestial point measured westward along the celestial equator from the zenith crossing | F24: Laugh sound | G24: =IF(F24="","",LEN(F24)) -> 11 | H24: Gotcha! | I24: =IF(H24="","",LEN(H24)) -> 7 | K24: =IF(J24="","",LEN(J24))
A25: =IF(B25="","",ROW()-1) -> 24 | B25: ad | C25: =IF(B25="","",LEN(TRIM(B25))) -> 2 | D25: Hard | E25: a public promotion of some product or service | G25: =IF(F25="","",LEN(F25)) | I25: =IF(H25="","",LEN(H25)) | K25: =IF(J25="","",LEN(J25))
A26: =IF(B26="","",ROW()-1) -> 25 | B26: hi | C26: =IF(B26="","",LEN(TRIM(B26))) -> 2 | D26: Hard | E26: an expression of greeting | G26: =IF(F26="","",LEN(F26)) | I26: =IF(H26="","",LEN(H26)) | K26: =IF(J26="","",LEN(J26))
A27: =IF(B27="","",ROW()-1) -> 26 | B27: ox | C27: =IF(B27="","",LEN(TRIM(B27))) -> 2 | D27: Hard | E27: an adult castrated bull of the genus Bos | G27: =IF(F27="","",LEN(F27)) | I27: =IF(H27="","",LEN(H27)) | K27: =IF(J27="","",LEN(J27))
A28: =IF(B28="","",ROW()-1) -> 27 | B28: pa | C28: =IF(B28="","",LEN(TRIM(B28))) -> 2 | D28: Hard | E28: an informal term for a father | G28: =IF(F28="","",LEN(F28)) | I28: =IF(H28="","",LEN(H28)) | K28: =IF(J28="","",LEN(J28))
A29: =IF(B29="","",ROW()-1) -> 28 | B29: ex | C29: =IF(B29="","",LEN(TRIM(B29))) -> 2 | D29: Rare | E29: a man who was formerly a certain woman's husband | G29: =IF(F29="","",LEN(F29)) | I29: =IF(H29="","",LEN(H29)) | K29: =IF(J29="","",LEN(J29))
A30: =IF(B30="","",ROW()-1) | C30: =IF(B30="","",LEN(TRIM(B30))) | G30: =IF(F30="","",LEN(F30)) | I30: =IF(H30="","",LEN(H30)) | K30: =IF(J30="","",LEN(J30))
A31: =IF(B31="","",ROW()-1) | C31: =IF(B31="","",LEN(TRIM(B31))) | G31: =IF(F31="","",LEN(F31)) | I31: =IF(H31="","",LEN(H31)) | K31: =IF(J31="","",LEN(J31))
A32: =IF(B32="","",ROW()-1) | C32: =IF(B32="","",LEN(TRIM(B32))) | G32: =IF(F32="","",LEN(F32)) | I32: =IF(H32="","",LEN(H32)) | K32: =IF(J32="","",LEN(J32))
A33: =IF(B33="","",ROW()-1) | C33: =IF(B33="","",LEN(TRIM(B33))) | G33: =IF(F33="","",LEN(F33)) | I33: =IF(H33="","",LEN(H33)) | K33: =IF(J33="","",LEN(J33))
A34: =IF(B34="","",ROW()-1) | C34: =IF(B34="","",LEN(TRIM(B34))) | G34: =IF(F34="","",LEN(F34)) | I34: =IF(H34="","",LEN(H34)) | K34: =IF(J34="","",LEN(J34))
A35: =IF(B35="","",ROW()-1) | C35: =IF(B35="","",LEN(TRIM(B35))) | G35: =IF(F35="","",LEN(F35)) | I35: =IF(H35="","",LEN(H35)) | K35: =IF(J35="","",LEN(J35))
A36: =IF(B36="","",ROW()-1) | C36: =IF(B36="","",LEN(TRIM(B36))) | G36: =IF(F36="","",LEN(F36)) | I36: =IF(H36="","",LEN(H36)) | K36: =IF(J36="","",LEN(J36))
A37: =IF(B37="","",ROW()-1) | C37: =IF(B37="","",LEN(TRIM(B37))) | G37: =IF(F37="","",LEN(F37)) | I37: =IF(H37="","",LEN(H37)) | K37: =IF(J37="","",LEN(J37))
A38: =IF(B38="","",ROW()-1) | C38: =IF(B38="","",LEN(TRIM(B38))) | G38: =IF(F38="","",LEN(F38)) | I38: =IF(H38="","",LEN(H38)) | K38: =IF(J38="","",LEN(J38))
A39: =IF(B39="","",ROW()-1) | C39: =IF(B39="","",LEN(TRIM(B39))) | G39: =IF(F39="","",LEN(F39)) | I39: =IF(H39="","",LEN(H39)) | K39: =IF(J39="","",LEN(J39))
A40: =IF(B40="","",ROW()-1) | C40: =IF(B40="","",LEN(TRIM(B40))) | G40: =IF(F40="","",LEN(F40)) | I40: =IF(H40="","",LEN(H40)) | K40: =IF(J40="","",LEN(J40))
A41: =IF(B41="","",ROW()-1) | C41: =IF(B41="","",LEN(TRIM(B41))) | G41: =IF(F41="","",LEN(F41)) | I41: =IF(H41="","",LEN(H41)) | K41: =IF(J41="","",LEN(J41))
... A529: =IF(B529="","",ROW()-1) | C529: =IF(B529="","",LEN(TRIM(B529))) | G529: =IF(F529="","",LEN(F529)) | I529: =IF(H529="","",LEN(H529)) | K529: =IF(J529="","",LEN(J529))

Sheet 3 letters
A1: ID | B1: Word | C1: Letters | D1: Difficulty | E1: Definition | F1: Clue 1 | G1: Len | H1: Clue 2 | I1: Len | J1: Clue 3 | K1: Len | L1: Notes
A2: =IF(B2="","",ROW()-1) -> 1 | B2: act | C2: =IF(B2="","",LEN(TRIM(B2))) -> 3 | D2: Easy | E2: perform an action, or work out or perform (an action) | F2: Do something | G2: =IF(F2="","",LEN(F2)) -> 12 | H2: Part of a play | I2: =IF(H2="","",LEN(H2)) -> 14 | K2: =IF(J2="","",LEN(J2))
A3: =IF(B3="","",ROW()-1) -> 2 | B3: add | C3: =IF(B3="","",LEN(TRIM(B3))) -> 3 | D3: Easy | E3: make an addition (to) | F3: Sum up | G3: =IF(F3="","",LEN(F3)) -> 6 | H3: Put in more | I3: =IF(H3="","",LEN(H3)) -> 11 | K3: =IF(J3="","",LEN(J3))
A4: =IF(B4="","",ROW()-1) -> 3 | B4: age | C4: =IF(B4="","",LEN(TRIM(B4))) -> 3 | D4: Easy | E4: how long something has existed | F4: Years lived | G4: =IF(F4="","",LEN(F4)) -> 11 | H4: How old you are | I4: =IF(H4="","",LEN(H4)) -> 15 | K4: =IF(J4="","",LEN(J4))
A5: =IF(B5="","",ROW()-1) -> 4 | B5: ago | C5: =IF(B5="","",LEN(TRIM(B5))) -> 3 | D5: Easy | E5: in the past | F5: In the past | G5: =IF(F5="","",LEN(F5)) -> 11 | H5: Long ___ | I5: =IF(H5="","",LEN(H5)) -> 8 | K5: =IF(J5="","",LEN(J5))
A6: =IF(B6="","",ROW()-1) -> 5 | B6: aid | C6: =IF(B6="","",LEN(TRIM(B6))) -> 3 | D6: Easy | E6: a resource | G6: =IF(F6="","",LEN(F6)) | I6: =IF(H6="","",LEN(H6)) | K6: =IF(J6="","",LEN(J6))
A7: =IF(B7="","",ROW()-1) -> 6 | B7: aim | C7: =IF(B7="","",LEN(TRIM(B7))) -> 3 | D7: Easy | E7: point or cause to go (blows, weapons, or objects such as photographic equipment) towards | F7: Goal | G7: =IF(F7="","",LEN(F7)) -> 4 | H7: Point at a target | I7: =IF(H7="","",LEN(H7)) -> 17 | K7: =IF(J7="","",LEN(J7))
A8: =IF(B8="","",ROW()-1) -> 7 | B8: air | C8: =IF(B8="","",LEN(TRIM(B8))) -> 3 | D8: Easy | E8: a mixture of gases (especially oxygen) required for breathing | F8: What we breathe | G8: =IF(F8="","",LEN(F8)) -> 15 | H8: Breeze | I8: =IF(H8="","",LEN(H8)) -> 6 | K8: =IF(J8="","",LEN(J8))
A9: =IF(B9="","",ROW()-1) -> 8 | B9: all | C9: =IF(B9="","",LEN(TRIM(B9))) -> 3 | D9: Easy | E9: quantifier | F9: Every one | G9: =IF(F9="","",LEN(F9)) -> 9 | H9: The whole lot | I9: =IF(H9="","",LEN(H9)) -> 13 | K9: =IF(J9="","",LEN(J9))
A10: =IF(B10="","",ROW()-1) -> 9 | B10: any | C10: =IF(B10="","",LEN(TRIM(B10))) -> 3 | D10: Easy | E10: one or some or every or all without specification | F10: Whichever | G10: =IF(F10="","",LEN(F10)) -> 9 | H10: Not ___ more | I10: =IF(H10="","",LEN(H10)) -> 12 | K10: =IF(J10="","",LEN(J10))
A11: =IF(B11="","",ROW()-1) -> 10 | B11: arm | C11: =IF(B11="","",LEN(TRIM(B11))) -> 3 | D11: Easy | E11: a human limb | F11: Limb with a hand | G11: =IF(F11="","",LEN(F11)) -> 16 | H11: Sleeve filler | I11: =IF(H11="","",LEN(H11)) -> 13 | K11: =IF(J11="","",LEN(J11))
A12: =IF(B12="","",ROW()-1) -> 11 | B12: art | C12: =IF(B12="","",LEN(TRIM(B12))) -> 3 | D12: Easy | E12: the products of human creativity | F12: Painting, e.g. | G12: =IF(F12="","",LEN(F12)) -> 14 | H12: Museum display | I12: =IF(H12="","",LEN(H12)) -> 14 | K12: =IF(J12="","",LEN(J12))
A13: =IF(B13="","",ROW()-1) -> 12 | B13: ask | C13: =IF(B13="","",LEN(TRIM(B13))) -> 3 | D13: Easy | E13: inquire about | F13: Pose a question | G13: =IF(F13="","",LEN(F13)) -> 15 | H13: Request | I13: =IF(H13="","",LEN(H13)) -> 7 | K13: =IF(J13="","",LEN(J13))
A14: =IF(B14="","",ROW()-1) -> 13 | B14: bad | C14: =IF(B14="","",LEN(TRIM(B14))) -> 3 | D14: Easy | E14: having undesirable or negative qualities | F14: Not good | G14: =IF(F14="","",LEN(F14)) -> 8 | H14: Naughty | I14: =IF(H14="","",LEN(H14)) -> 7 | K14: =IF(J14="","",LEN(J14))
A15: =IF(B15="","",ROW()-1) -> 14 | B15: ban | C15: =IF(B15="","",LEN(TRIM(B15))) -> 3 | D15: Easy | E15: forbid the public distribution of ( a movie or a newspaper) | G15: =IF(F15="","",LEN(F15)) | I15: =IF(H15="","",LEN(H15)) | K15: =IF(J15="","",LEN(J15))
A16: =IF(B16="","",ROW()-1) -> 15 | B16: bar | C16: =IF(B16="","",LEN(TRIM(B16))) -> 3 | D16: Easy | E16: a room or establishment where alcoholic drinks are served over a counter | F16: Candy ___ | G16: =IF(F16="","",LEN(F16)) -> 9 | H16: Rod | I16: =IF(H16="","",LEN(H16)) -> 3 | K16: =IF(J16="","",LEN(J16))
A17: =IF(B17="","",ROW()-1) -> 16 | B17: bed | C17: =IF(B17="","",LEN(TRIM(B17))) -> 3 | D17: Easy | E17: a piece of furniture that provides a place to sleep | F17: Place to sleep | G17: =IF(F17="","",LEN(F17)) -> 14 | H17: Garden plot | I17: =IF(H17="","",LEN(H17)) -> 11 | K17: =IF(J17="","",LEN(J17))
A18: =IF(B18="","",ROW()-1) -> 17 | B18: bet | C18: =IF(B18="","",LEN(TRIM(B18))) -> 3 | D18: Easy | E18: the money risked on a gamble | F18: Wager | G18: =IF(F18="","",LEN(F18)) -> 5 | H18: Gamble | I18: =IF(H18="","",LEN(H18)) -> 6 | K18: =IF(J18="","",LEN(J18))
A19: =IF(B19="","",ROW()-1) -> 18 | B19: bid | C19: =IF(B19="","",LEN(TRIM(B19))) -> 3 | D19: Easy | E19: propose a payment | F19: Offer at auction | G19: =IF(F19="","",LEN(F19)) -> 16 | H19: Attempt | I19: =IF(H19="","",LEN(H19)) -> 7 | K19: =IF(J19="","",LEN(J19))
A20: =IF(B20="","",ROW()-1) -> 19 | B20: big | C20: =IF(B20="","",LEN(TRIM(B20))) -> 3 | D20: Easy | E20: above average in size or number or quantity or magnitude or extent | F20: Large | G20: =IF(F20="","",LEN(F20)) -> 5 | H20: Huge | I20: =IF(H20="","",LEN(H20)) -> 4 | K20: =IF(J20="","",LEN(J20))
A21: =IF(B21="","",ROW()-1) -> 20 | B21: bit | C21: =IF(B21="","",LEN(TRIM(B21))) -> 3 | D21: Easy | E21: a small piece or quantity of something | G21: =IF(F21="","",LEN(F21)) | I21: =IF(H21="","",LEN(H21)) | K21: =IF(J21="","",LEN(J21))
A22: =IF(B22="","",ROW()-1) -> 21 | B22: box | C22: =IF(B22="","",LEN(TRIM(B22))) -> 3 | D22: Easy | E22: a (usually rectangular) container | G22: =IF(F22="","",LEN(F22)) | I22: =IF(H22="","",LEN(H22)) | K22: =IF(J22="","",LEN(J22))
A23: =IF(B23="","",ROW()-1) -> 22 | B23: boy | C23: =IF(B23="","",LEN(TRIM(B23))) -> 3 | D23: Easy | E23: a youthful male person | G23: =IF(F23="","",LEN(F23)) | I23: =IF(H23="","",LEN(H23)) | K23: =IF(J23="","",LEN(J23))
A24: =IF(B24="","",ROW()-1) -> 23 | B24: bug | C24: =IF(B24="","",LEN(TRIM(B24))) -> 3 | D24: Easy | E24: general term for any insect or similar creeping or crawling invertebrate | F24: Insect | G24: =IF(F24="","",LEN(F24)) -> 6 | H24: Glitch | I24: =IF(H24="","",LEN(H24)) -> 6 | K24: =IF(J24="","",LEN(J24))
A25: =IF(B25="","",ROW()-1) -> 24 | B25: bus | C25: =IF(B25="","",LEN(TRIM(B25))) -> 3 | D25: Easy | E25: a vehicle carrying many passengers | F25: School ___ | G25: =IF(F25="","",LEN(F25)) -> 10 | H25: Public transport | I25: =IF(H25="","",LEN(H25)) -> 16 | K25: =IF(J25="","",LEN(J25))
A26: =IF(B26="","",ROW()-1) -> 25 | B26: but | C26: =IF(B26="","",LEN(TRIM(B26))) -> 3 | D26: Easy | E26: and nothing more | F26: However | G26: =IF(F26="","",LEN(F26)) -> 7 | H26: Yet | I26: =IF(H26="","",LEN(H26)) -> 3 | K26: =IF(J26="","",LEN(J26))
A27: =IF(B27="","",ROW()-1) -> 26 | B27: buy | C27: =IF(B27="","",LEN(TRIM(B27))) -> 3 | D27: Easy | E27: obtain by purchase | G27: =IF(F27="","",LEN(F27)) | I27: =IF(H27="","",LEN(H27)) | K27: =IF(J27="","",LEN(J27))
A28: =IF(B28="","",ROW()-1) -> 27 | B28: can | C28: =IF(B28="","",LEN(TRIM(B28))) -> 3 | D28: Easy | E28: preserve in a can or tin | G28: =IF(F28="","",LEN(F28)) | I28: =IF(H28="","",LEN(H28)) | K28: =IF(J28="","",LEN(J28))
A29: =IF(B29="","",ROW()-1) -> 28 | B29: car | C29: =IF(B29="","",LEN(TRIM(B29))) -> 3 | D29: Easy | E29: a motor vehicle with four wheels | F29: Auto | G29: =IF(F29="","",LEN(F29)) -> 4 | H29: Sedan | I29: =IF(H29="","",LEN(H29)) -> 5 | K29: =IF(J29="","",LEN(J29))
A30: =IF(B30="","",ROW()-1) -> 29 | B30: cat | C30: =IF(B30="","",LEN(TRIM(B30))) -> 3 | D30: Easy | E30: feline mammal usually having thick soft fur and no ability to roar: domestic cats | F30: Purring pet | G30: =IF(F30="","",LEN(F30)) -> 11 | H30: Kitty | I30: =IF(H30="","",LEN(H30)) -> 5 | K30: =IF(J30="","",LEN(J30))
A31: =IF(B31="","",ROW()-1) -> 30 | B31: cry | C31: =IF(B31="","",LEN(TRIM(B31))) -> 3 | D31: Easy | E31: a loud utterance | G31: =IF(F31="","",LEN(F31)) | I31: =IF(H31="","",LEN(H31)) | K31: =IF(J31="","",LEN(J31))
A32: =IF(B32="","",ROW()-1) -> 31 | B32: cup | C32: =IF(B32="","",LEN(TRIM(B32))) -> 3 | D32: Easy | E32: a small open container usually used for drinking | F32: Mug | G32: =IF(F32="","",LEN(F32)) -> 3 | H32: Trophy | I32: =IF(H32="","",LEN(H32)) -> 6 | K32: =IF(J32="","",LEN(J32))
A33: =IF(B33="","",ROW()-1) -> 32 | B33: cut | C33: =IF(B33="","",LEN(TRIM(B33))) -> 3 | D33: Easy | E33: separate with or as if with an instrument | F33: Slice | G33: =IF(F33="","",LEN(F33)) -> 5 | H33: Snip | I33: =IF(H33="","",LEN(H33)) -> 4 | K33: =IF(J33="","",LEN(J33))
A34: =IF(B34="","",ROW()-1) -> 33 | B34: day | C34: =IF(B34="","",LEN(TRIM(B34))) -> 3 | D34: Easy | E34: time for Earth to make a complete rotation on its axis | F34: 24 hours | G34: =IF(F34="","",LEN(F34)) -> 8 | H34: Not night | I34: =IF(H34="","",LEN(H34)) -> 9 | K34: =IF(J34="","",LEN(J34))
A35: =IF(B35="","",ROW()-1) -> 34 | B35: doe | C35: =IF(B35="","",LEN(TRIM(B35))) -> 3 | D35: Easy | E35: the federal department responsible for maintaining a national energy policy of the United States | F35: Female deer | G35: =IF(F35="","",LEN(F35)) -> 11 | H35: Mother deer | I35: =IF(H35="","",LEN(H35)) -> 11 | K35: =IF(J35="","",LEN(J35))
A36: =IF(B36="","",ROW()-1) -> 35 | B36: dog | C36: =IF(B36="","",LEN(TRIM(B36))) -> 3 | D36: Easy | E36: a member of the genus Canis (probably descended from the common wolf) that has been domesticated by man since prehistoric times | G36: =IF(F36="","",LEN(F36)) | I36: =IF(H36="","",LEN(H36)) | K36: =IF(J36="","",LEN(J36))
A37: =IF(B37="","",ROW()-1) -> 36 | B37: dry | C37: =IF(B37="","",LEN(TRIM(B37))) -> 3 | D37: Easy | E37: remove the moisture from and make dry | F37: Not wet | G37: =IF(F37="","",LEN(F37)) -> 7 | H37: Arid | I37: =IF(H37="","",LEN(H37)) -> 4 | K37: =IF(J37="","",LEN(J37))
A38: =IF(B38="","",ROW()-1) -> 37 | B38: due | C38: =IF(B38="","",LEN(TRIM(B38))) -> 3 | D38: Easy | E38: owed and payable immediately or on demand | F38: Owed | G38: =IF(F38="","",LEN(F38)) -> 4 | H38: Expected | I38: =IF(H38="","",LEN(H38)) -> 8 | K38: =IF(J38="","",LEN(J38))
A39: =IF(B39="","",ROW()-1) -> 38 | B39: eat | C39: =IF(B39="","",LEN(TRIM(B39))) -> 3 | D39: Easy | E39: take in solid food | F39: Dine | G39: =IF(F39="","",LEN(F39)) -> 4 | H39: Have a meal | I39: =IF(H39="","",LEN(H39)) -> 11 | K39: =IF(J39="","",LEN(J39))
A40: =IF(B40="","",ROW()-1) -> 39 | B40: end | C40: =IF(B40="","",LEN(TRIM(B40))) -> 3 | D40: Easy | E40: either extremity of something that has length | F40: Finish | G40: =IF(F40="","",LEN(F40)) -> 6 | H40: Conclusion | I40: =IF(H40="","",LEN(H40)) -> 10 | K40: =IF(J40="","",LEN(J40))
...

Sheet 4 letters
A1: ID | B1: Word | C1: Letters | D1: Difficulty | E1: Definition | F1: Clue 1 | G1: Len | H1: Clue 2 | I1: Len | J1: Clue 3 | K1: Len | L1: Notes
A2: =IF(B2="","",ROW()-1) -> 1 | B2: able | C2: =IF(B2="","",LEN(TRIM(B2))) -> 4 | D2: Easy | E2: (usually followed by `to') having the necessary means or skill or know-how or authority to do something | F2: Capable | G2: =IF(F2="","",LEN(F2)) -> 7 | H2: Having the skill | I2: =IF(H2="","",LEN(H2)) -> 16 | K2: =IF(J2="","",LEN(J2))
A3: =IF(B3="","",ROW()-1) -> 2 | B3: also | C3: =IF(B3="","",LEN(TRIM(B3))) -> 4 | D3: Easy | E3: in addition | G3: =IF(F3="","",LEN(F3)) | I3: =IF(H3="","",LEN(H3)) | K3: =IF(J3="","",LEN(J3))
A4: =IF(B4="","",ROW()-1) -> 3 | B4: area | C4: =IF(B4="","",LEN(TRIM(B4))) -> 4 | D4: Easy | E4: a particular geographical region of indefinite boundary (usually serving some special purpose or distinguished by its people or culture or geography) | F4: Region | G4: =IF(F4="","",LEN(F4)) -> 6 | H4: Zone | I4: =IF(H4="","",LEN(H4)) -> 4 | K4: =IF(J4="","",LEN(J4))
A5: =IF(B5="","",ROW()-1) -> 4 | B5: army | C5: =IF(B5="","",LEN(TRIM(B5))) -> 4 | D5: Easy | E5: a permanent organization of the military land forces of a nation or state | F5: Soldiers | G5: =IF(F5="","",LEN(F5)) -> 8 | H5: Military force | I5: =IF(H5="","",LEN(H5)) -> 14 | K5: =IF(J5="","",LEN(J5))
A6: =IF(B6="","",ROW()-1) -> 5 | B6: away | C6: =IF(B6="","",LEN(TRIM(B6))) -> 4 | D6: Easy | E6: from a particular thing or place or position (`forth' is obsolete) | G6: =IF(F6="","",LEN(F6)) | I6: =IF(H6="","",LEN(H6)) | K6: =IF(J6="","",LEN(J6))
A7: =IF(B7="","",ROW()-1) -> 6 | B7: back | C7: =IF(B7="","",LEN(TRIM(B7))) -> 4 | D7: Easy | E7: in or to or toward a former location | G7: =IF(F7="","",LEN(F7)) | I7: =IF(H7="","",LEN(H7)) | K7: =IF(J7="","",LEN(J7))
A8: =IF(B8="","",ROW()-1) -> 7 | B8: ball | C8: =IF(B8="","",LEN(TRIM(B8))) -> 4 | D8: Easy | E8: round object that is hit or thrown or kicked in games | F8: Round toy | G8: =IF(F8="","",LEN(F8)) -> 9 | H8: Dance with gowns | I8: =IF(H8="","",LEN(H8)) -> 16 | K8: =IF(J8="","",LEN(J8))
A9: =IF(B9="","",ROW()-1) -> 8 | B9: band | C9: =IF(B9="","",LEN(TRIM(B9))) -> 4 | D9: Easy | E9: an unofficial association of people or groups | G9: =IF(F9="","",LEN(F9)) | I9: =IF(H9="","",LEN(H9)) | K9: =IF(J9="","",LEN(J9))
A10: =IF(B10="","",ROW()-1) -> 9 | B10: bank | C10: =IF(B10="","",LEN(TRIM(B10))) -> 4 | D10: Easy | E10: sloping land (especially the slope beside a body of water) | G10: =IF(F10="","",LEN(F10)) | I10: =IF(H10="","",LEN(H10)) | K10: =IF(J10="","",LEN(J10))
A11: =IF(B11="","",ROW()-1) -> 10 | B11: base | C11: =IF(B11="","",LEN(TRIM(B11))) -> 4 | D11: Easy | E11: installation from which a military force initiates operations | F11: Bottom | G11: =IF(F11="","",LEN(F11)) -> 6 | H11: Foundation | I11: =IF(H11="","",LEN(H11)) -> 10 | K11: =IF(J11="","",LEN(J11))
A12: =IF(B12="","",ROW()-1) -> 11 | B12: bear | C12: =IF(B12="","",LEN(TRIM(B12))) -> 4 | D12: Easy | E12: have | F12: Grizzly | G12: =IF(F12="","",LEN(F12)) -> 7 | H12: Put up with | I12: =IF(H12="","",LEN(H12)) -> 11 | K12: =IF(J12="","",LEN(J12))
A13: =IF(B13="","",ROW()-1) -> 12 | B13: best | C13: =IF(B13="","",LEN(TRIM(B13))) -> 4 | D13: Easy | E13: the supreme effort one can make | G13: =IF(F13="","",LEN(F13)) | I13: =IF(H13="","",LEN(H13)) | K13: =IF(J13="","",LEN(J13))
A14: =IF(B14="","",ROW()-1) -> 13 | B14: bill | C14: =IF(B14="","",LEN(TRIM(B14))) -> 4 | D14: Easy | E14: a statute in draft before it becomes law | G14: =IF(F14="","",LEN(F14)) | I14: =IF(H14="","",LEN(H14)) | K14: =IF(J14="","",LEN(J14))
A15: =IF(B15="","",ROW()-1) -> 14 | B15: bind | C15: =IF(B15="","",LEN(TRIM(B15))) -> 4 | D15: Easy | E15: stick to firmly | G15: =IF(F15="","",LEN(F15)) | I15: =IF(H15="","",LEN(H15)) | K15: =IF(J15="","",LEN(J15))
A16: =IF(B16="","",ROW()-1) -> 15 | B16: bite | C16: =IF(B16="","",LEN(TRIM(B16))) -> 4 | D16: Easy | E16: to grip, cut off, or tear with or as if with the teeth or jaws | F16: Nibble | G16: =IF(F16="","",LEN(F16)) -> 6 | H16: Small mouthful | I16: =IF(H16="","",LEN(H16)) -> 14 | K16: =IF(J16="","",LEN(J16))
A17: =IF(B17="","",ROW()-1) -> 16 | B17: blow | C17: =IF(B17="","",LEN(TRIM(B17))) -> 4 | D17: Easy | E17: exhale hard | G17: =IF(F17="","",LEN(F17)) | I17: =IF(H17="","",LEN(H17)) | K17: =IF(J17="","",LEN(J17))
A18: =IF(B18="","",ROW()-1) -> 17 | B18: blue | C18: =IF(B18="","",LEN(TRIM(B18))) -> 4 | D18: Easy | E18: blue color or pigment | F18: Sky color | G18: =IF(F18="","",LEN(F18)) -> 9 | H18: Feeling sad | I18: =IF(H18="","",LEN(H18)) -> 11 | K18: =IF(J18="","",LEN(J18))
A19: =IF(B19="","",ROW()-1) -> 18 | B19: boat | C19: =IF(B19="","",LEN(TRIM(B19))) -> 4 | D19: Easy | E19: a small vessel for travel on water | G19: =IF(F19="","",LEN(F19)) | I19: =IF(H19="","",LEN(H19)) | K19: =IF(J19="","",LEN(J19))
A20: =IF(B20="","",ROW()-1) -> 19 | B20: body | C20: =IF(B20="","",LEN(TRIM(B20))) -> 4 | D20: Easy | E20: the entire structure of an organism (an animal, plant, or human being) | F20: Torso and limbs | G20: =IF(F20="","",LEN(F20)) -> 15 | H20: Main part | I20: =IF(H20="","",LEN(H20)) -> 9 | K20: =IF(J20="","",LEN(J20))
A21: =IF(B21="","",ROW()-1) -> 20 | B21: book | C21: =IF(B21="","",LEN(TRIM(B21))) -> 4 | D21: Easy | E21: a written work or composition that has been published (printed on pages bound together) | G21: =IF(F21="","",LEN(F21)) | I21: =IF(H21="","",LEN(H21)) | K21: =IF(J21="","",LEN(J21))
A22: =IF(B22="","",ROW()-1) -> 21 | B22: boot | C22: =IF(B22="","",LEN(TRIM(B22))) -> 4 | D22: Easy | E22: footwear that covers the whole foot and lower leg | G22: =IF(F22="","",LEN(F22)) | I22: =IF(H22="","",LEN(H22)) | K22: =IF(J22="","",LEN(J22))
A23: =IF(B23="","",ROW()-1) -> 22 | B23: bore | C23: =IF(B23="","",LEN(TRIM(B23))) -> 4 | D23: Easy | E23: cause to be bored | F23: Dull person | G23: =IF(F23="","",LEN(F23)) -> 11 | H23: Tire out | I23: =IF(H23="","",LEN(H23)) -> 8 | K23: =IF(J23="","",LEN(J23))
A24: =IF(B24="","",ROW()-1) -> 23 | B24: both | C24: =IF(B24="","",LEN(TRIM(B24))) -> 4 | D24: Easy | E24: (used with count nouns) two considered together | G24: =IF(F24="","",LEN(F24)) | I24: =IF(H24="","",LEN(H24)) | K24: =IF(J24="","",LEN(J24))
A25: =IF(B25="","",ROW()-1) -> 24 | B25: bulk | C25: =IF(B25="","",LEN(TRIM(B25))) -> 4 | D25: Easy | E25: the property resulting from being or relating to the greater in number of two parts | G25: =IF(F25="","",LEN(F25)) | I25: =IF(H25="","",LEN(H25)) | K25: =IF(J25="","",LEN(J25))
A26: =IF(B26="","",ROW()-1) -> 25 | B26: bury | C26: =IF(B26="","",LEN(TRIM(B26))) -> 4 | D26: Easy | E26: cover from sight | G26: =IF(F26="","",LEN(F26)) | I26: =IF(H26="","",LEN(H26)) | K26: =IF(J26="","",LEN(J26))
A27: =IF(B27="","",ROW()-1) -> 26 | B27: busy | C27: =IF(B27="","",LEN(TRIM(B27))) -> 4 | D27: Easy | E27: actively or fully engaged or occupied | G27: =IF(F27="","",LEN(F27)) | I27: =IF(H27="","",LEN(H27)) | K27: =IF(J27="","",LEN(J27))
A28: =IF(B28="","",ROW()-1) -> 27 | B28: call | C28: =IF(B28="","",LEN(TRIM(B28))) -> 4 | D28: Easy | E28: assign a specified (usually proper) proper name to | G28: =IF(F28="","",LEN(F28)) | I28: =IF(H28="","",LEN(H28)) | K28: =IF(J28="","",LEN(J28))
A29: =IF(B29="","",ROW()-1) -> 28 | B29: card | C29: =IF(B29="","",LEN(TRIM(B29))) -> 4 | D29: Easy | E29: one of a set of small pieces of stiff paper marked in various ways and used for playing games or for telling fortunes | G29: =IF(F29="","",LEN(F29)) | I29: =IF(H29="","",LEN(H29)) | K29: =IF(J29="","",LEN(J29))
A30: =IF(B30="","",ROW()-1) -> 29 | B30: care | C30: =IF(B30="","",LEN(TRIM(B30))) -> 4 | D30: Easy | E30: the work of providing treatment for or attending to someone or something | G30: =IF(F30="","",LEN(F30)) | I30: =IF(H30="","",LEN(H30)) | K30: =IF(J30="","",LEN(J30))
A31: =IF(B31="","",ROW()-1) -> 30 | B31: case | C31: =IF(B31="","",LEN(TRIM(B31))) -> 4 | D31: Easy | E31: an occurrence of something | F31: Box | G31: =IF(F31="","",LEN(F31)) -> 3 | H31: Court matter | I31: =IF(H31="","",LEN(H31)) -> 12 | K31: =IF(J31="","",LEN(J31))
A32: =IF(B32="","",ROW()-1) -> 31 | B32: cell | C32: =IF(B32="","",LEN(TRIM(B32))) -> 4 | D32: Easy | E32: any small compartment | F32: Prison room | G32: =IF(F32="","",LEN(F32)) -> 11 | H32: Phone, for short | I32: =IF(H32="","",LEN(H32)) -> 16 | K32: =IF(J32="","",LEN(J32))
A33: =IF(B33="","",ROW()-1) -> 32 | B33: cent | C33: =IF(B33="","",LEN(TRIM(B33))) -> 4 | D33: Easy | E33: a fractional monetary unit of several countries | G33: =IF(F33="","",LEN(F33)) | I33: =IF(H33="","",LEN(H33)) | K33: =IF(J33="","",LEN(J33))
A34: =IF(B34="","",ROW()-1) -> 33 | B34: chip | C34: =IF(B34="","",LEN(TRIM(B34))) -> 4 | D34: Easy | E34: a small fragment of something broken off from the whole | G34: =IF(F34="","",LEN(F34)) | I34: =IF(H34="","",LEN(H34)) | K34: =IF(J34="","",LEN(J34))
A35: =IF(B35="","",ROW()-1) -> 34 | B35: city | C35: =IF(B35="","",LEN(TRIM(B35))) -> 4 | D35: Easy | E35: a large and densely populated urban area | G35: =IF(F35="","",LEN(F35)) | I35: =IF(H35="","",LEN(H35)) | K35: =IF(J35="","",LEN(J35))
A36: =IF(B36="","",ROW()-1) -> 35 | B36: club | C36: =IF(B36="","",LEN(TRIM(B36))) -> 4 | D36: Easy | E36: a team of professional baseball players who play and travel together | G36: =IF(F36="","",LEN(F36)) | I36: =IF(H36="","",LEN(H36)) | K36: =IF(J36="","",LEN(J36))
A37: =IF(B37="","",ROW()-1) -> 36 | B37: clue | C37: =IF(B37="","",LEN(TRIM(B37))) -> 4 | D37: Easy | E37: a slight indication | G37: =IF(F37="","",LEN(F37)) | I37: =IF(H37="","",LEN(H37)) | K37: =IF(J37="","",LEN(J37))
A38: =IF(B38="","",ROW()-1) -> 37 | B38: code | C38: =IF(B38="","",LEN(TRIM(B38))) -> 4 | D38: Easy | E38: a set of rules or principles or laws (especially written ones) | F38: Secret message | G38: =IF(F38="","",LEN(F38)) -> 14 | H38: Zip ___ | I38: =IF(H38="","",LEN(H38)) -> 7 | K38: =IF(J38="","",LEN(J38))
A39: =IF(B39="","",ROW()-1) -> 38 | B39: cold | C39: =IF(B39="","",LEN(TRIM(B39))) -> 4 | D39: Easy | E39: having a low or inadequate temperature or feeling a sensation of coldness or having been made cold by e.g. ice or refrigeration | F39: Chilly | G39: =IF(F39="","",LEN(F39)) -> 6 | H39: Common illness | I39: =IF(H39="","",LEN(H39)) -> 14 | K39: =IF(J39="","",LEN(J39))
A40: =IF(B40="","",ROW()-1) -> 39 | B40: come | C40: =IF(B40="","",LEN(TRIM(B40))) -> 4 | D40: Easy | E40: move toward, travel toward something or somebody or approach something or somebody | G40: =IF(F40="","",LEN(F40)) | I40: =IF(H40="","",LEN(H40)) | K40: =IF(J40="","",LEN(J40))
...

Sheet 5 letters
A1: ID | B1: Word | C1: Letters | D1: Difficulty | E1: Definition | F1: Clue 1 | G1: Len | H1: Clue 2 | I1: Len | J1: Clue 3 | K1: Len | L1: Notes
A2: =IF(B2="","",ROW()-1) -> 1 | B2: about | C2: =IF(B2="","",LEN(TRIM(B2))) -> 5 | D2: Easy | E2: (of quantities) imprecise but fairly close to correct | G2: =IF(F2="","",LEN(F2)) | I2: =IF(H2="","",LEN(H2)) | K2: =IF(J2="","",LEN(J2))
A3: =IF(B3="","",ROW()-1) -> 2 | B3: above | C3: =IF(B3="","",LEN(TRIM(B3))) -> 5 | D3: Easy | E3: at an earlier place | G3: =IF(F3="","",LEN(F3)) | I3: =IF(H3="","",LEN(H3)) | K3: =IF(J3="","",LEN(J3))
A4: =IF(B4="","",ROW()-1) -> 3 | B4: abuse | C4: =IF(B4="","",LEN(TRIM(B4))) -> 5 | D4: Easy | E4: treat badly | F4: Treat badly | G4: =IF(F4="","",LEN(F4)) -> 11 | H4: Misuse | I4: =IF(H4="","",LEN(H4)) -> 6 | K4: =IF(J4="","",LEN(J4))
A5: =IF(B5="","",ROW()-1) -> 4 | B5: admit | C5: =IF(B5="","",LEN(TRIM(B5))) -> 5 | D5: Easy | E5: declare to be true or admit the existence or reality or truth of | G5: =IF(F5="","",LEN(F5)) | I5: =IF(H5="","",LEN(H5)) | K5: =IF(J5="","",LEN(J5))
A6: =IF(B6="","",ROW()-1) -> 5 | B6: adopt | C6: =IF(B6="","",LEN(TRIM(B6))) -> 5 | D6: Easy | E6: choose and follow | G6: =IF(F6="","",LEN(F6)) | I6: =IF(H6="","",LEN(H6)) | K6: =IF(J6="","",LEN(J6))
A7: =IF(B7="","",ROW()-1) -> 6 | B7: after | C7: =IF(B7="","",LEN(TRIM(B7))) -> 5 | D7: Easy | E7: happening at a time subsequent to a reference time | G7: =IF(F7="","",LEN(F7)) | I7: =IF(H7="","",LEN(H7)) | K7: =IF(J7="","",LEN(J7))
A8: =IF(B8="","",ROW()-1) -> 7 | B8: again | C8: =IF(B8="","",LEN(TRIM(B8))) -> 5 | D8: Easy | E8: anew | F8: Once more | G8: =IF(F8="","",LEN(F8)) -> 9 | H8: One more time | I8: =IF(H8="","",LEN(H8)) -> 13 | K8: =IF(J8="","",LEN(J8))
A9: =IF(B9="","",ROW()-1) -> 8 | B9: agree | C9: =IF(B9="","",LEN(TRIM(B9))) -> 5 | D9: Easy | E9: be in accord | G9: =IF(F9="","",LEN(F9)) | I9: =IF(H9="","",LEN(H9)) | K9: =IF(J9="","",LEN(J9))
A10: =IF(B10="","",ROW()-1) -> 9 | B10: ahead | C10: =IF(B10="","",LEN(TRIM(B10))) -> 5 | D10: Easy | E10: at or in the front | F10: In front | G10: =IF(F10="","",LEN(F10)) -> 8 | H10: Go ___ (proceed) | I10: =IF(H10="","",LEN(H10)) -> 16 | K10: =IF(J10="","",LEN(J10))
A11: =IF(B11="","",ROW()-1) -> 10 | B11: alarm | C11: =IF(B11="","",LEN(TRIM(B11))) -> 5 | D11: Easy | E11: fear resulting from the awareness of danger | G11: =IF(F11="","",LEN(F11)) | I11: =IF(H11="","",LEN(H11)) | K11: =IF(J11="","",LEN(J11))
A12: =IF(B12="","",ROW()-1) -> 11 | B12: album | C12: =IF(B12="","",LEN(TRIM(B12))) -> 5 | D12: Easy | E12: one or more recordings issued together | G12: =IF(F12="","",LEN(F12)) | I12: =IF(H12="","",LEN(H12)) | K12: =IF(J12="","",LEN(J12))
A13: =IF(B13="","",ROW()-1) -> 12 | B13: alive | C13: =IF(B13="","",LEN(TRIM(B13))) -> 5 | D13: Easy | E13: possessing life | G13: =IF(F13="","",LEN(F13)) | I13: =IF(H13="","",LEN(H13)) | K13: =IF(J13="","",LEN(J13))
A14: =IF(B14="","",ROW()-1) -> 13 | B14: allow | C14: =IF(B14="","",LEN(TRIM(B14))) -> 5 | D14: Easy | E14: make it possible through a specific action or lack of action for something to happen | G14: =IF(F14="","",LEN(F14)) | I14: =IF(H14="","",LEN(H14)) | K14: =IF(J14="","",LEN(J14))
A15: =IF(B15="","",ROW()-1) -> 14 | B15: alone | C15: =IF(B15="","",LEN(TRIM(B15))) -> 5 | D15: Easy | E15: isolated from others | G15: =IF(F15="","",LEN(F15)) | I15: =IF(H15="","",LEN(H15)) | K15: =IF(J15="","",LEN(J15))
A16: =IF(B16="","",ROW()-1) -> 15 | B16: along | C16: =IF(B16="","",LEN(TRIM(B16))) -> 5 | D16: Easy | E16: with a forward motion | G16: =IF(F16="","",LEN(F16)) | I16: =IF(H16="","",LEN(H16)) | K16: =IF(J16="","",LEN(J16))
A17: =IF(B17="","",ROW()-1) -> 16 | B17: alter | C17: =IF(B17="","",LEN(TRIM(B17))) -> 5 | D17: Easy | E17: cause to change | G17: =IF(F17="","",LEN(F17)) | I17: =IF(H17="","",LEN(H17)) | K17: =IF(J17="","",LEN(J17))
A18: =IF(B18="","",ROW()-1) -> 17 | B18: amuse | C18: =IF(B18="","",LEN(TRIM(B18))) -> 5 | D18: Easy | E18: occupy in an agreeable, entertaining or pleasant fashion | G18: =IF(F18="","",LEN(F18)) | I18: =IF(H18="","",LEN(H18)) | K18: =IF(J18="","",LEN(J18))
A19: =IF(B19="","",ROW()-1) -> 18 | B19: angle | C19: =IF(B19="","",LEN(TRIM(B19))) -> 5 | D19: Easy | E19: the space between two lines or planes that intersect | F19: Corner measure | G19: =IF(F19="","",LEN(F19)) -> 14 | H19: Point of view | I19: =IF(H19="","",LEN(H19)) -> 13 | K19: =IF(J19="","",LEN(J19))
A20: =IF(B20="","",ROW()-1) -> 19 | B20: angry | C20: =IF(B20="","",LEN(TRIM(B20))) -> 5 | D20: Easy | E20: feeling or showing anger | G20: =IF(F20="","",LEN(F20)) | I20: =IF(H20="","",LEN(H20)) | K20: =IF(J20="","",LEN(J20))
A21: =IF(B21="","",ROW()-1) -> 20 | B21: annoy | C21: =IF(B21="","",LEN(TRIM(B21))) -> 5 | D21: Easy | E21: cause annoyance in | G21: =IF(F21="","",LEN(F21)) | I21: =IF(H21="","",LEN(H21)) | K21: =IF(J21="","",LEN(J21))
A22: =IF(B22="","",ROW()-1) -> 21 | B22: apart | C22: =IF(B22="","",LEN(TRIM(B22))) -> 5 | D22: Easy | E22: separated or at a distance in place or position or time | G22: =IF(F22="","",LEN(F22)) | I22: =IF(H22="","",LEN(H22)) | K22: =IF(J22="","",LEN(J22))
A23: =IF(B23="","",ROW()-1) -> 22 | B23: apple | C23: =IF(B23="","",LEN(TRIM(B23))) -> 5 | D23: Easy | E23: fruit with red or yellow or green skin and sweet to tart crisp whitish flesh | G23: =IF(F23="","",LEN(F23)) | I23: =IF(H23="","",LEN(H23)) | K23: =IF(J23="","",LEN(J23))
A24: =IF(B24="","",ROW()-1) -> 23 | B24: apply | C24: =IF(B24="","",LEN(TRIM(B24))) -> 5 | D24: Easy | E24: put into service | G24: =IF(F24="","",LEN(F24)) | I24: =IF(H24="","",LEN(H24)) | K24: =IF(J24="","",LEN(J24))
A25: =IF(B25="","",ROW()-1) -> 24 | B25: argue | C25: =IF(B25="","",LEN(TRIM(B25))) -> 5 | D25: Easy | E25: present reasons and arguments | G25: =IF(F25="","",LEN(F25)) | I25: =IF(H25="","",LEN(H25)) | K25: =IF(J25="","",LEN(J25))
A26: =IF(B26="","",ROW()-1) -> 25 | B26: arise | C26: =IF(B26="","",LEN(TRIM(B26))) -> 5 | D26: Easy | E26: come into existence | F26: Get up | G26: =IF(F26="","",LEN(F26)) -> 6 | H26: Come up | I26: =IF(H26="","",LEN(H26)) -> 7 | K26: =IF(J26="","",LEN(J26))
A27: =IF(B27="","",ROW()-1) -> 26 | B27: aside | C27: =IF(B27="","",LEN(TRIM(B27))) -> 5 | D27: Easy | E27: on or to one side | G27: =IF(F27="","",LEN(F27)) | I27: =IF(H27="","",LEN(H27)) | K27: =IF(J27="","",LEN(J27))
A28: =IF(B28="","",ROW()-1) -> 27 | B28: avoid | C28: =IF(B28="","",LEN(TRIM(B28))) -> 5 | D28: Easy | E28: stay clear from | G28: =IF(F28="","",LEN(F28)) | I28: =IF(H28="","",LEN(H28)) | K28: =IF(J28="","",LEN(J28))
A29: =IF(B29="","",ROW()-1) -> 28 | B29: awake | C29: =IF(B29="","",LEN(TRIM(B29))) -> 5 | D29: Easy | E29: stop sleeping | G29: =IF(F29="","",LEN(F29)) | I29: =IF(H29="","",LEN(H29)) | K29: =IF(J29="","",LEN(J29))
A30: =IF(B30="","",ROW()-1) -> 29 | B30: award | C30: =IF(B30="","",LEN(TRIM(B30))) -> 5 | D30: Easy | E30: a grant made by a law court | F30: Prize | G30: =IF(F30="","",LEN(F30)) -> 5 | H30: Trophy | I30: =IF(H30="","",LEN(H30)) -> 6 | K30: =IF(J30="","",LEN(J30))
A31: =IF(B31="","",ROW()-1) -> 30 | B31: aware | C31: =IF(B31="","",LEN(TRIM(B31))) -> 5 | D31: Easy | E31: (sometimes followed by `of') having or showing knowledge or understanding or realization or perception | F31: Knowing | G31: =IF(F31="","",LEN(F31)) -> 7 | H31: Conscious | I31: =IF(H31="","",LEN(H31)) -> 9 | K31: =IF(J31="","",LEN(J31))
A32: =IF(B32="","",ROW()-1) -> 31 | B32: awful | C32: =IF(B32="","",LEN(TRIM(B32))) -> 5 | D32: Easy | E32: exceptionally bad or displeasing | G32: =IF(F32="","",LEN(F32)) | I32: =IF(H32="","",LEN(H32)) | K32: =IF(J32="","",LEN(J32))
A33: =IF(B33="","",ROW()-1) -> 32 | B33: basic | C33: =IF(B33="","",LEN(TRIM(B33))) -> 5 | D33: Easy | E33: pertaining to or constituting a base or basis | G33: =IF(F33="","",LEN(F33)) | I33: =IF(H33="","",LEN(H33)) | K33: =IF(J33="","",LEN(J33))
A34: =IF(B34="","",ROW()-1) -> 33 | B34: basis | C34: =IF(B34="","",LEN(TRIM(B34))) -> 5 | D34: Easy | E34: a relation that provides the foundation for something | F34: Foundation | G34: =IF(F34="","",LEN(F34)) -> 10 | H34: Grounds | I34: =IF(H34="","",LEN(H34)) -> 7 | K34: =IF(J34="","",LEN(J34))
A35: =IF(B35="","",ROW()-1) -> 34 | B35: begin | C35: =IF(B35="","",LEN(TRIM(B35))) -> 5 | D35: Easy | E35: take the first step or steps in carrying out an action | G35: =IF(F35="","",LEN(F35)) | I35: =IF(H35="","",LEN(H35)) | K35: =IF(J35="","",LEN(J35))
A36: =IF(B36="","",ROW()-1) -> 35 | B36: being | C36: =IF(B36="","",LEN(TRIM(B36))) -> 5 | D36: Easy | E36: the state or fact of existing | G36: =IF(F36="","",LEN(F36)) | I36: =IF(H36="","",LEN(H36)) | K36: =IF(J36="","",LEN(J36))
A37: =IF(B37="","",ROW()-1) -> 36 | B37: below | C37: =IF(B37="","",LEN(TRIM(B37))) -> 5 | D37: Easy | E37: in or to a place that is lower | F37: Under | G37: =IF(F37="","",LEN(F37)) -> 5 | H37: Beneath | I37: =IF(H37="","",LEN(H37)) -> 7 | K37: =IF(J37="","",LEN(J37))
A38: =IF(B38="","",ROW()-1) -> 37 | B38: black | C38: =IF(B38="","",LEN(TRIM(B38))) -> 5 | D38: Easy | E38: being of the achromatic color of maximum darkness | G38: =IF(F38="","",LEN(F38)) | I38: =IF(H38="","",LEN(H38)) | K38: =IF(J38="","",LEN(J38))
A39: =IF(B39="","",ROW()-1) -> 38 | B39: blame | C39: =IF(B39="","",LEN(TRIM(B39))) -> 5 | D39: Easy | E39: put or pin the blame on | G39: =IF(F39="","",LEN(F39)) | I39: =IF(H39="","",LEN(H39)) | K39: =IF(J39="","",LEN(J39))
A40: =IF(B40="","",ROW()-1) -> 39 | B40: blank | C40: =IF(B40="","",LEN(TRIM(B40))) -> 5 | D40: Easy | E40: (of a surface) not written or printed on | G40: =IF(F40="","",LEN(F40)) | I40: =IF(H40="","",LEN(H40)) | K40: =IF(J40="","",LEN(J40))
...

Sheet 6 letters
A1: ID | B1: Word | C1: Letters | D1: Difficulty | E1: Definition | F1: Clue 1 | G1: Len | H1: Clue 2 | I1: Len | J1: Clue 3 | K1: Len | L1: Notes
A2: =IF(B2="","",ROW()-1) -> 1 | B2: accept | C2: =IF(B2="","",LEN(TRIM(B2))) -> 6 | D2: Easy | E2: consider or hold as true | G2: =IF(F2="","",LEN(F2)) | I2: =IF(H2="","",LEN(H2)) | K2: =IF(J2="","",LEN(J2))
A3: =IF(B3="","",ROW()-1) -> 2 | B3: access | C3: =IF(B3="","",LEN(TRIM(B3))) -> 6 | D3: Easy | E3: the right to enter | F3: Way in | G3: =IF(F3="","",LEN(F3)) -> 6 | H3: Right to enter | I3: =IF(H3="","",LEN(H3)) -> 14 | K3: =IF(J3="","",LEN(J3))
A4: =IF(B4="","",ROW()-1) -> 3 | B4: accord | C4: =IF(B4="","",LEN(TRIM(B4))) -> 6 | D4: Easy | E4: go together | G4: =IF(F4="","",LEN(F4)) | I4: =IF(H4="","",LEN(H4)) | K4: =IF(J4="","",LEN(J4))
A5: =IF(B5="","",ROW()-1) -> 4 | B5: across | C5: =IF(B5="","",LEN(TRIM(B5))) -> 6 | D5: Easy | E5: to the opposite side | G5: =IF(F5="","",LEN(F5)) | I5: =IF(H5="","",LEN(H5)) | K5: =IF(J5="","",LEN(J5))
A6: =IF(B6="","",ROW()-1) -> 5 | B6: action | C6: =IF(B6="","",LEN(TRIM(B6))) -> 6 | D6: Easy | E6: something done (usually as opposed to something said) | F6: Deed | G6: =IF(F6="","",LEN(F6)) -> 4 | H6: Lights, camera, ___! | I6: =IF(H6="","",LEN(H6)) -> 20 | K6: =IF(J6="","",LEN(J6))
A7: =IF(B7="","",ROW()-1) -> 6 | B7: active | C7: =IF(B7="","",LEN(TRIM(B7))) -> 6 | D7: Easy | E7: tending to become more severe or wider in scope | G7: =IF(F7="","",LEN(F7)) | I7: =IF(H7="","",LEN(H7)) | K7: =IF(J7="","",LEN(J7))
A8: =IF(B8="","",ROW()-1) -> 7 | B8: actual | C8: =IF(B8="","",LEN(TRIM(B8))) -> 6 | D8: Easy | E8: presently existing in fact and not merely potential or possible | G8: =IF(F8="","",LEN(F8)) | I8: =IF(H8="","",LEN(H8)) | K8: =IF(J8="","",LEN(J8))
A9: =IF(B9="","",ROW()-1) -> 8 | B9: adjust | C9: =IF(B9="","",LEN(TRIM(B9))) -> 6 | D9: Easy | E9: alter or regulate so as to achieve accuracy or conform to a standard | G9: =IF(F9="","",LEN(F9)) | I9: =IF(H9="","",LEN(H9)) | K9: =IF(J9="","",LEN(J9))
A10: =IF(B10="","",ROW()-1) -> 9 | B10: advice | C10: =IF(B10="","",LEN(TRIM(B10))) -> 6 | D10: Easy | E10: a proposal for an appropriate course of action | G10: =IF(F10="","",LEN(F10)) | I10: =IF(H10="","",LEN(H10)) | K10: =IF(J10="","",LEN(J10))
A11: =IF(B11="","",ROW()-1) -> 10 | B11: advise | C11: =IF(B11="","",LEN(TRIM(B11))) -> 6 | D11: Easy | E11: give advice to | G11: =IF(F11="","",LEN(F11)) | I11: =IF(H11="","",LEN(H11)) | K11: =IF(J11="","",LEN(J11))
A12: =IF(B12="","",ROW()-1) -> 11 | B12: affair | C12: =IF(B12="","",LEN(TRIM(B12))) -> 6 | D12: Easy | E12: a vaguely specified concern | G12: =IF(F12="","",LEN(F12)) | I12: =IF(H12="","",LEN(H12)) | K12: =IF(J12="","",LEN(J12))
A13: =IF(B13="","",ROW()-1) -> 12 | B13: affect | C13: =IF(B13="","",LEN(TRIM(B13))) -> 6 | D13: Easy | E13: have an effect upon | G13: =IF(F13="","",LEN(F13)) | I13: =IF(H13="","",LEN(H13)) | K13: =IF(J13="","",LEN(J13))
A14: =IF(B14="","",ROW()-1) -> 13 | B14: afford | C14: =IF(B14="","",LEN(TRIM(B14))) -> 6 | D14: Easy | E14: be able to spare or give up | G14: =IF(F14="","",LEN(F14)) | I14: =IF(H14="","",LEN(H14)) | K14: =IF(J14="","",LEN(J14))
A15: =IF(B15="","",ROW()-1) -> 14 | B15: afraid | C15: =IF(B15="","",LEN(TRIM(B15))) -> 6 | D15: Easy | E15: filled with fear or apprehension | G15: =IF(F15="","",LEN(F15)) | I15: =IF(H15="","",LEN(H15)) | K15: =IF(J15="","",LEN(J15))
A16: =IF(B16="","",ROW()-1) -> 15 | B16: agency | C16: =IF(B16="","",LEN(TRIM(B16))) -> 6 | D16: Easy | E16: an administrative unit of government | G16: =IF(F16="","",LEN(F16)) | I16: =IF(H16="","",LEN(H16)) | K16: =IF(J16="","",LEN(J16))
A17: =IF(B17="","",ROW()-1) -> 16 | B17: agreed | C17: =IF(B17="","",LEN(TRIM(B17))) -> 6 | D17: Easy | E17: united by being of the same opinion | F17: Settled | G17: =IF(F17="","",LEN(F17)) -> 7 | H17: All said yes | I17: =IF(H17="","",LEN(H17)) -> 12 | K17: =IF(J17="","",LEN(J17))
A18: =IF(B18="","",ROW()-1) -> 17 | B18: almost | C18: =IF(B18="","",LEN(TRIM(B18))) -> 6 | D18: Easy | E18: (of actions or states) slightly short of or not quite accomplished | G18: =IF(F18="","",LEN(F18)) | I18: =IF(H18="","",LEN(H18)) | K18: =IF(J18="","",LEN(J18))
A19: =IF(B19="","",ROW()-1) -> 18 | B19: always | C19: =IF(B19="","",LEN(TRIM(B19))) -> 6 | D19: Easy | E19: at all times | G19: =IF(F19="","",LEN(F19)) | I19: =IF(H19="","",LEN(H19)) | K19: =IF(J19="","",LEN(J19))
A20: =IF(B20="","",ROW()-1) -> 19 | B20: amount | C20: =IF(B20="","",LEN(TRIM(B20))) -> 6 | D20: Easy | E20: a quantity of money | G20: =IF(F20="","",LEN(F20)) | I20: =IF(H20="","",LEN(H20)) | K20: =IF(J20="","",LEN(J20))
A21: =IF(B21="","",ROW()-1) -> 20 | B21: animal | C21: =IF(B21="","",LEN(TRIM(B21))) -> 6 | D21: Easy | E21: a living organism characterized by voluntary movement | F21: Beast | G21: =IF(F21="","",LEN(F21)) -> 5 | H21: Zoo creature | I21: =IF(H21="","",LEN(H21)) -> 12 | K21: =IF(J21="","",LEN(J21))
A22: =IF(B22="","",ROW()-1) -> 21 | B22: annual | C22: =IF(B22="","",LEN(TRIM(B22))) -> 6 | D22: Easy | E22: completing its life cycle within a year | G22: =IF(F22="","",LEN(F22)) | I22: =IF(H22="","",LEN(H22)) | K22: =IF(J22="","",LEN(J22))
A23: =IF(B23="","",ROW()-1) -> 22 | B23: answer | C23: =IF(B23="","",LEN(TRIM(B23))) -> 6 | D23: Easy | E23: react verbally | G23: =IF(F23="","",LEN(F23)) | I23: =IF(H23="","",LEN(H23)) | K23: =IF(J23="","",LEN(J23))
A24: =IF(B24="","",ROW()-1) -> 23 | B24: anyway | C24: =IF(B24="","",LEN(TRIM(B24))) -> 6 | D24: Easy | E24: used to indicate that a statement explains or supports a previous statement | G24: =IF(F24="","",LEN(F24)) | I24: =IF(H24="","",LEN(H24)) | K24: =IF(J24="","",LEN(J24))
A25: =IF(B25="","",ROW()-1) -> 24 | B25: appeal | C25: =IF(B25="","",LEN(TRIM(B25))) -> 6 | D25: Easy | E25: earnest or urgent request | F25: Charm | G25: =IF(F25="","",LEN(F25)) -> 5 | H25: Ask earnestly | I25: =IF(H25="","",LEN(H25)) -> 13 | K25: =IF(J25="","",LEN(J25))
A26: =IF(B26="","",ROW()-1) -> 25 | B26: appear | C26: =IF(B26="","",LEN(TRIM(B26))) -> 6 | D26: Easy | E26: give a certain impression or have a certain outward aspect | F26: Show up | G26: =IF(F26="","",LEN(F26)) -> 7 | H26: Come into view | I26: =IF(H26="","",LEN(H26)) -> 14 | K26: =IF(J26="","",LEN(J26))
A27: =IF(B27="","",ROW()-1) -> 26 | B27: around | C27: =IF(B27="","",LEN(TRIM(B27))) -> 6 | D27: Easy | E27: in the area or vicinity | G27: =IF(F27="","",LEN(F27)) | I27: =IF(H27="","",LEN(H27)) | K27: =IF(J27="","",LEN(J27))
A28: =IF(B28="","",ROW()-1) -> 27 | B28: arrive | C28: =IF(B28="","",LEN(TRIM(B28))) -> 6 | D28: Easy | E28: reach a destination | G28: =IF(F28="","",LEN(F28)) | I28: =IF(H28="","",LEN(H28)) | K28: =IF(J28="","",LEN(J28))
A29: =IF(B29="","",ROW()-1) -> 28 | B29: artist | C29: =IF(B29="","",LEN(TRIM(B29))) -> 6 | D29: Easy | E29: a person whose creative work shows sensitivity and imagination | F29: Painter | G29: =IF(F29="","",LEN(F29)) -> 7 | H29: Creative person | I29: =IF(H29="","",LEN(H29)) -> 15 | K29: =IF(J29="","",LEN(J29))
A30: =IF(B30="","",ROW()-1) -> 29 | B30: asleep | C30: =IF(B30="","",LEN(TRIM(B30))) -> 6 | D30: Easy | E30: in a state of sleep | F30: Napping | G30: =IF(F30="","",LEN(F30)) -> 7 | H30: In dreamland | I30: =IF(H30="","",LEN(H30)) -> 12 | K30: =IF(J30="","",LEN(J30))
A31: =IF(B31="","",ROW()-1) -> 30 | B31: aspect | C31: =IF(B31="","",LEN(TRIM(B31))) -> 6 | D31: Easy | E31: a distinct feature or element in a problem | G31: =IF(F31="","",LEN(F31)) | I31: =IF(H31="","",LEN(H31)) | K31: =IF(J31="","",LEN(J31))
A32: =IF(B32="","",ROW()-1) -> 31 | B32: assume | C32: =IF(B32="","",LEN(TRIM(B32))) -> 6 | D32: Easy | E32: take to be the case or to be true | G32: =IF(F32="","",LEN(F32)) | I32: =IF(H32="","",LEN(H32)) | K32: =IF(J32="","",LEN(J32))
A33: =IF(B33="","",ROW()-1) -> 32 | B33: assure | C33: =IF(B33="","",LEN(TRIM(B33))) -> 6 | D33: Easy | E33: make certain of | F33: Promise | G33: =IF(F33="","",LEN(F33)) -> 7 | H33: Guarantee | I33: =IF(H33="","",LEN(H33)) -> 9 | K33: =IF(J33="","",LEN(J33))
A34: =IF(B34="","",ROW()-1) -> 33 | B34: attach | C34: =IF(B34="","",LEN(TRIM(B34))) -> 6 | D34: Easy | E34: cause to be attached | F34: Fasten | G34: =IF(F34="","",LEN(F34)) -> 6 | H34: Add to an email | I34: =IF(H34="","",LEN(H34)) -> 15 | K34: =IF(J34="","",LEN(J34))
A35: =IF(B35="","",ROW()-1) -> 34 | B35: attack | C35: =IF(B35="","",LEN(TRIM(B35))) -> 6 | D35: Easy | E35: (military) an offensive against an enemy (using weapons) | G35: =IF(F35="","",LEN(F35)) | I35: =IF(H35="","",LEN(H35)) | K35: =IF(J35="","",LEN(J35))
A36: =IF(B36="","",ROW()-1) -> 35 | B36: attend | C36: =IF(B36="","",LEN(TRIM(B36))) -> 6 | D36: Easy | E36: be present at (meetings, church services, university), etc. | G36: =IF(F36="","",LEN(F36)) | I36: =IF(H36="","",LEN(H36)) | K36: =IF(J36="","",LEN(J36))
A37: =IF(B37="","",ROW()-1) -> 36 | B37: author | C37: =IF(B37="","",LEN(TRIM(B37))) -> 6 | D37: Easy | E37: writes (books or stories or articles or the like) professionally (for pay) | G37: =IF(F37="","",LEN(F37)) | I37: =IF(H37="","",LEN(H37)) | K37: =IF(J37="","",LEN(J37))
A38: =IF(B38="","",ROW()-1) -> 37 | B38: autumn | C38: =IF(B38="","",LEN(TRIM(B38))) -> 6 | D38: Easy | E38: the season when the leaves fall from the trees | G38: =IF(F38="","",LEN(F38)) | I38: =IF(H38="","",LEN(H38)) | K38: =IF(J38="","",LEN(J38))
A39: =IF(B39="","",ROW()-1) -> 38 | B39: become | C39: =IF(B39="","",LEN(TRIM(B39))) -> 6 | D39: Easy | E39: enter or assume a certain state or condition | G39: =IF(F39="","",LEN(F39)) | I39: =IF(H39="","",LEN(H39)) | K39: =IF(J39="","",LEN(J39))
A40: =IF(B40="","",ROW()-1) -> 39 | B40: before | C40: =IF(B40="","",LEN(TRIM(B40))) -> 6 | D40: Easy | E40: earlier in time | G40: =IF(F40="","",LEN(F40)) | I40: =IF(H40="","",LEN(H40)) | K40: =IF(J40="","",LEN(J40))
...

Sheet 7 letters
A1: ID | B1: Word | C1: Letters | D1: Difficulty | E1: Definition | F1: Clue 1 | G1: Len | H1: Clue 2 | I1: Len | J1: Clue 3 | K1: Len | L1: Notes
A2: =IF(B2="","",ROW()-1) -> 1 | B2: ability | C2: =IF(B2="","",LEN(TRIM(B2))) -> 7 | D2: Easy | E2: the quality of being able to perform | G2: =IF(F2="","",LEN(F2)) | I2: =IF(H2="","",LEN(H2)) | K2: =IF(J2="","",LEN(J2))
A3: =IF(B3="","",ROW()-1) -> 2 | B3: absence | C3: =IF(B3="","",LEN(TRIM(B3))) -> 7 | D3: Easy | E3: the state of being absent | G3: =IF(F3="","",LEN(F3)) | I3: =IF(H3="","",LEN(H3)) | K3: =IF(J3="","",LEN(J3))
A4: =IF(B4="","",ROW()-1) -> 3 | B4: account | C4: =IF(B4="","",LEN(TRIM(B4))) -> 7 | D4: Easy | E4: a record or narrative description of past events | G4: =IF(F4="","",LEN(F4)) | I4: =IF(H4="","",LEN(H4)) | K4: =IF(J4="","",LEN(J4))
A5: =IF(B5="","",ROW()-1) -> 4 | B5: achieve | C5: =IF(B5="","",LEN(TRIM(B5))) -> 7 | D5: Easy | E5: to gain with effort | G5: =IF(F5="","",LEN(F5)) | I5: =IF(H5="","",LEN(H5)) | K5: =IF(J5="","",LEN(J5))
A6: =IF(B6="","",ROW()-1) -> 5 | B6: acquire | C6: =IF(B6="","",LEN(TRIM(B6))) -> 7 | D6: Easy | E6: come into the possession of something concrete or abstract | G6: =IF(F6="","",LEN(F6)) | I6: =IF(H6="","",LEN(H6)) | K6: =IF(J6="","",LEN(J6))
A7: =IF(B7="","",ROW()-1) -> 6 | B7: address | C7: =IF(B7="","",LEN(TRIM(B7))) -> 7 | D7: Easy | E7: speak to | G7: =IF(F7="","",LEN(F7)) | I7: =IF(H7="","",LEN(H7)) | K7: =IF(J7="","",LEN(J7))
A8: =IF(B8="","",ROW()-1) -> 7 | B8: adopted | C8: =IF(B8="","",LEN(TRIM(B8))) -> 7 | D8: Easy | E8: acquired as your own by free choice | G8: =IF(F8="","",LEN(F8)) | I8: =IF(H8="","",LEN(H8)) | K8: =IF(J8="","",LEN(J8))
A9: =IF(B9="","",ROW()-1) -> 8 | B9: advance | C9: =IF(B9="","",LEN(TRIM(B9))) -> 7 | D9: Easy | E9: move forward, also in the metaphorical sense | G9: =IF(F9="","",LEN(F9)) | I9: =IF(H9="","",LEN(H9)) | K9: =IF(J9="","",LEN(J9))
A10: =IF(B10="","",ROW()-1) -> 9 | B10: already | C10: =IF(B10="","",LEN(TRIM(B10))) -> 7 | D10: Easy | E10: prior to a specified or implied time | G10: =IF(F10="","",LEN(F10)) | I10: =IF(H10="","",LEN(H10)) | K10: =IF(J10="","",LEN(J10))
A11: =IF(B11="","",ROW()-1) -> 10 | B11: altered | C11: =IF(B11="","",LEN(TRIM(B11))) -> 7 | D11: Easy | E11: changed in form or character without becoming something else | G11: =IF(F11="","",LEN(F11)) | I11: =IF(H11="","",LEN(H11)) | K11: =IF(J11="","",LEN(J11))
A12: =IF(B12="","",ROW()-1) -> 11 | B12: ancient | C12: =IF(B12="","",LEN(TRIM(B12))) -> 7 | D12: Easy | E12: belonging to times long past especially of the historical period before the fall of the Western Roman Empire | G12: =IF(F12="","",LEN(F12)) | I12: =IF(H12="","",LEN(H12)) | K12: =IF(J12="","",LEN(J12))
A13: =IF(B13="","",ROW()-1) -> 12 | B13: another | C13: =IF(B13="","",LEN(TRIM(B13))) -> 7 | D13: Easy | E13: any of various alternatives | G13: =IF(F13="","",LEN(F13)) | I13: =IF(H13="","",LEN(H13)) | K13: =IF(J13="","",LEN(J13))
... A3002: =IF(B3002="","",ROW()-1) -> 3001 | B3002: yardage | C3002: =IF(B3002="","",LEN(TRIM(B3002))) -> 7 | D3002: Rare | E3002: distance measured in the aggregate number of yards | G3002: =IF(F3002="","",LEN(F3002)) | I3002: =IF(H3002="","",LEN(H3002)) | K3002: =IF(J3002="","",LEN(J3002))
A3003: =IF(B3003="","",ROW()-1) | C3003: =IF(B3003="","",LEN(TRIM(B3003))) | G3003: =IF(F3003="","",LEN(F3003)) | I3003: =IF(H3003="","",LEN(H3003)) | K3003: =IF(J3003="","",LEN(J3003))
A3004: =IF(B3004="","",ROW()-1) | C3004: =IF(B3004="","",LEN(TRIM(B3004))) | G3004: =IF(F3004="","",LEN(F3004)) | I3004: =IF(H3004="","",LEN(H3004)) | K3004: =IF(J3004="","",LEN(J3004))
A3005: =IF(B3005="","",ROW()-1) | C3005: =IF(B3005="","",LEN(TRIM(B3005))) | G3005: =IF(F3005="","",LEN(F3005)) | I3005: =IF(H3005="","",LEN(H3005)) | K3005: =IF(J3005="","",LEN(J3005))
A3006: =IF(B3006="","",ROW()-1) | C3006: =IF(B3006="","",LEN(TRIM(B3006))) | G3006: =IF(F3006="","",LEN(F3006)) | I3006: =IF(H3006="","",LEN(H3006)) | K3006: =IF(J3006="","",LEN(J3006))
A3007: =IF(B3007="","",ROW()-1) | C3007: =IF(B3007="","",LEN(TRIM(B3007))) | G3007: =IF(F3007="","",LEN(F3007)) | I3007: =IF(H3007="","",LEN(H3007)) | K3007: =IF(J3007="","",LEN(J3007))
A3008: =IF(B3008="","",ROW()-1) | C3008: =IF(B3008="","",LEN(TRIM(B3008))) | G3008: =IF(F3008="","",LEN(F3008)) | I3008: =IF(H3008="","",LEN(H3008)) | K3008: =IF(J3008="","",LEN(J3008))
A3009: =IF(B3009="","",ROW()-1) | C3009: =IF(B3009="","",LEN(TRIM(B3009))) | G3009: =IF(F3009="","",LEN(F3009)) | I3009: =IF(H3009="","",LEN(H3009)) | K3009: =IF(J3009="","",LEN(J3009))
A3010: =IF(B3010="","",ROW()-1) | C3010: =IF(B3010="","",LEN(TRIM(B3010))) | G3010: =IF(F3010="","",LEN(F3010)) | I3010: =IF(H3010="","",LEN(H3010)) | K3010: =IF(J3010="","",LEN(J3010))
A3011: =IF(B3011="","",ROW()-1) | C3011: =IF(B3011="","",LEN(TRIM(B3011))) | G3011: =IF(F3011="","",LEN(F3011)) | I3011: =IF(H3011="","",LEN(H3011)) | K3011: =IF(J3011="","",LEN(J3011))
A3012: =IF(B3012="","",ROW()-1) | C3012: =IF(B3012="","",LEN(TRIM(B3012))) | G3012: =IF(F3012="","",LEN(F3012)) | I3012: =IF(H3012="","",LEN(H3012)) | K3012: =IF(J3012="","",LEN(J3012))
A3013: =IF(B3013="","",ROW()-1) | C3013: =IF(B3013="","",LEN(TRIM(B3013))) | G3013: =IF(F3013="","",LEN(F3013)) | I3013: =IF(H3013="","",LEN(H3013)) | K3013: =IF(J3013="","",LEN(J3013))
A3014: =IF(B3014="","",ROW()-1) | C3014: =IF(B3014="","",LEN(TRIM(B3014))) | G3014: =IF(F3014="","",LEN(F3014)) | I3014: =IF(H3014="","",LEN(H3014)) | K3014: =IF(J3014="","",LEN(J3014))
... A3502: =IF(B3502="","",ROW()-1) | C3502: =IF(B3502="","",LEN(TRIM(B3502))) | G3502: =IF(F3502="","",LEN(F3502)) | I3502: =IF(H3502="","",LEN(H3502)) | K3502: =IF(J3502="","",LEN(J3502))

Sheet 8 letters
A1: ID | B1: Word | C1: Letters | D1: Difficulty | E1: Definition | F1: Clue 1 | G1: Len | H1: Clue 2 | I1: Len | J1: Clue 3 | K1: Len | L1: Notes
A2: =IF(B2="","",ROW()-1) -> 1 | B2: absolute | C2: =IF(B2="","",LEN(TRIM(B2))) -> 8 | D2: Easy | E2: perfect or complete or pure | G2: =IF(F2="","",LEN(F2)) | I2: =IF(H2="","",LEN(H2)) | K2: =IF(J2="","",LEN(J2))
